Workbook

Sheet Backlog
A1: ID | B1: Typ zgłoszenia | C1: Epik ID | D1: Epik | E1: Podsumowanie | F1: Opis (Jako / Chcę / Aby) | G1: Kryteria akceptacji | H1: Priorytet | I1: Story points | J1: Faza | K1: Ref. FR/NFR | L1: Stan wdrożenia
A2: E1 | B2: Epik | C2: E1 | D2: Rejestracja i zarządzanie nieobecnościami | E2: Rejestracja i zarządzanie nieobecnościami | F2: Pracownicy samodzielnie wpisują i edytują nieobecności bez blokad pliku.
A3: US-A1 | B3: Historyjka | C3: E1 | D3: Rejestracja i zarządzanie nieobecnościami | E3: Samoobsługowy wpis nieobecności | F3: Jako pracownik (UoP/B2B/OUT) chcę wpisać własną nieobecność (typ, data od–do), aby zaplanować dni wolne bez plików Excel. | G3: • Formularz dostępny po zalogowaniu • Od logowania do zapisu maks. 3 kliknięcia • Wpis zapisywany i widoczny natychmiast | H3: Must | I3: 5 | J3: MVP | K3: FR-A1 | L3: Zrealizowane
A4: US-A2 | B4: Historyjka | C4: E1 | D4: Rejestracja i zarządzanie nieobecnościami | E4: Wpis przez zakres dat z pomijaniem weekendów i świąt | F4: Jako pracownik chcę podać zakres dat i mieć policzone tylko dni robocze, aby nie liczyć ręcznie weekendów i świąt. | G4: • Weekendy nie są naliczane • Dni z tabeli świąt nie są naliczane • Liczba dni roboczych pokazana przed zapisem | H4: Must | I4: 5 | J4: MVP | K4: FR-A2 | L4: Zrealizowane
A5: US-A3 | B5: Historyjka | C5: E1 | D5: Rejestracja i zarządzanie nieobecnościami | E5: Obsługa niepełnych dni (pół dnia / godziny) | F5: Jako pracownik chcę wpisać pół dnia (AM/PM) lub konkretne godziny, aby odwzorować krótsze nieobecności w systemie 8-godzinnym. | G5: • Wybór AM/PM lub zakresu godzin • Przeliczenie na ułamek dnia w balansie i capacity | H5: Should | I5: 5 | J5: Faza 2 | K5: FR-A3 | L5: Zrealizowane
A6: US-A4 | B6: Historyjka | C6: E1 | D6: Rejestracja i zarządzanie nieobecnościami | E6: Edycja i usuwanie własnych wpisów | F6: Jako pracownik chcę edytować lub usunąć swój wpis, aby poprawić pomyłkę bez udziału innych. | G6: • Edycja/usuwanie tylko własnych wpisów • Balans i capacity aktualizują się < 1 s | H6: Must | I6: 3 | J6: MVP | K6: FR-A4 | L6: Zrealizowane
A7: US-A5 | B7: Historyjka | C7: E1 | D7: Rejestracja i zarządzanie nieobecnościami | E7: Korekta wpisów zespołu przez lidera | F7: Jako lider chcę poprawić wpis członka zespołu na etapie weryfikacji, aby skorygować błędy bez czekania na pracownika. | G7: • Lider edytuje wpisy tylko w swoim zespole • Zmiana odnotowana w historii (FR-I1) | H7: Should | I7: 3 | J7: Faza 2 | K7: FR-A5 | L7: Zrealizowane
A8: US-A6 | B8: Historyjka | C8: E1 | D8: Rejestracja i zarządzanie nieobecnościami | E8: Wielodostęp w czasie rzeczywistym | F8: Jako zespół chcę wpisywać nieobecności równocześnie z innymi, aby uniknąć blokad i „kolejek” znanych z Excela. | G8: • Brak blokad typu check-out • Równoczesne zapisy nie powodują utraty danych ani konfliktów | H8: Must | I8: 8 | J8: MVP | K8: FR-A6 | L8: Zrealizowane
A9: US-A7 | B9: Historyjka | C9: E1 | D9: Rejestracja i zarządzanie nieobecnościami | E9: Walidacja wpisu | F9: Jako pracownik chcę otrzymać czytelny komunikat przy błędnym wpisie, aby uniknąć przekroczenia puli i kolizji. | G9: • Kontrola przekroczenia puli, kolizji i zakresu dat • Zapis zablokowany do czasu poprawy • Komunikat wskazuje konkretny problem | H9: Must | I9: 3 | J9: MVP | K9: FR-A7 | L9: Zrealizowane
A10: US-A8 | B10: Historyjka | C10: E1 | D10: Rejestracja i zarządzanie nieobecnościami | E10: Wybór typu nieobecności z listy | F10: Jako pracownik chcę wybrać typ nieobecności z listy administratora, aby umożliwić właściwe wyliczenia (np. L4). | G10: • Lista typów konfigurowalna przez admina • Prezentacja w UI jednolita niezależnie od typu (D1) | H10: Should | I10: 2 | J10: MVP | K10: FR-A8 | L10: Zrealizowane
A11: US-A9 | B11: Historyjka | C11: E1 | D11: Rejestracja i zarządzanie nieobecnościami | E11: Proaktywna asysta przy wpisie | F11: Jako pracownik chcę widzieć dostępny balans i kolizje przed zapisem, aby ograniczyć liczbę błędnych wpisów. | G11: • Dostępny balans i skutek wpisu widoczne na żywo • Dni niedostępne wyróżnione • Ostrzeżenie o kolizji przed zapisem | H11: Should | I11: 5 | J11: Faza 2 | K11: FR-A9 | L11: Zrealizowane
A12: US-A10 | B12: Historyjka | C12: E1 | D12: Rejestracja i zarządzanie nieobecnościami | E12: Operacje masowe | F12: Jako lider / administrator chcę wpisać nieobecność dla wielu osób naraz, aby obsłużyć np. wyjazd całego squadu jednym działaniem. | G12: • Jeden formularz tworzy wpisy dla wielu osób • Walidacja wykonywana per osoba | H12: Could | I12: 5 | J12: Faza 3 | K12: FR-A10 | L12: Zrealizowane
A13: US-A11 | B13: Historyjka | C13: E1 | D13: Rejestracja i zarządzanie nieobecnościami | E13: Potwierdzenia i cofanie operacji | F13: Jako pracownik chcę potwierdzać usuwanie i móc cofnąć ostatnią operację, aby uniknąć przypadkowej utraty wpisu. | G13: • Usunięcie wymaga potwierdzenia • Funkcja „cofnij” przywraca wpis i balans | H13: Should | I13: 3 | J13: Faza 2 | K13: FR-A11 | L13: Zrealizowane
A14: E2 | B14: Epik | C14: E2 | D14: Wyliczenia, pula i balans | E14: Wyliczenia, pula i balans | F14: Poprawne, odrębne liczenie urlopu dla UoP i B2B/OUT wraz z przypadkami brzegowymi.
A15: US-B1 | B15: Historyjka | C15: E2 | D15: Wyliczenia, pula i balans | E15: Odrębne reguły liczenia UoP vs B2B/OUT | F15: Jako system chcę liczyć dni wg roku kalendarzowego (UoP) i budżetowego (B2B/OUT), aby zapewnić poprawne salda dla obu form (warunek akceptacji). | G15: • UoP rozliczany w roku kalendarzowym • B2B/OUT w roku budżetowym (−1 mc) • Właściwy okres dobierany wg formy zatrudnienia | H15: Must | I15: 8 | J15: MVP | K15: FR-B1 | L15: Zrealizowane
A16: US-B2 | B16: Historyjka | C16: E2 | D16: Wyliczenia, pula i balans | E16: Licznik na żywo: pula / wykorzystano / pozostało | F16: Jako pracownik chcę widzieć aktualny licznik wykorzystania, aby wiedzieć ile dni zostało do rozplanowania. | G16: • Trzy wartości: pula, wykorzystano, pozostało • Aktualizacja < 1 s po zmianie wpisu | H16: Must | I16: 5 | J16: MVP | K16: FR-B2 | L16: Zrealizowane
A17: US-B3 | B17: Historyjka | C17: E2 | D17: Wyliczenia, pula i balans | E17: Pula urlopu: globalna + korekta indywidualna | F17: Jako administrator chcę ustawić pulę globalnie i korygować ją per osoba, aby zarządzać limitami bez integracji z TETA. | G17: • Pula globalna propaguje się do pracowników • Korekta indywidualna nadpisuje wartość globalną | H17: Must | I17: 5 | J17: MVP | K17: FR-B3 | L17: Zrealizowane
A18: US-B4 | B18: Historyjka | C18: E2 | D18: Wyliczenia, pula i balans | E18: Urlop zaległy i minimum do pozostawienia | F18: Jako pracownik (UoP) chcę widzieć urlop zaległy i minimum do pozostawienia, aby planować wykorzystanie zgodnie z zasadami. | G18: • Balans uwzględnia urlop zaległy • Minimum do pozostawienia wyróżnione | H18: Should | I18: 3 | J18: Faza 2 | K18: FR-B4 | L18: Zrealizowane
A19: US-B5 | B19: Historyjka | C19: E2 | D19: Wyliczenia, pula i balans | E19: Algorytm L4 (capacity, bez obniżania puli) | F19: Jako system chcę traktować L4 dla UoP jako wpływające na capacity, lecz nie na pulę urlopu, aby poprawnie odwzorować chorobowe. | G19: • Wpis L4 zmniejsza dostępność w capacity • Wpis L4 nie pomniejsza puli urlopu UoP | H19: Must | I19: 3 | J19: MVP | K19: FR-B5 | L19: Zrealizowane
A20: US-B6 | B20: Historyjka | C20: E2 | D20: Wyliczenia, pula i balans | E20: Wymiar B2B/OUT ustalany per okres | F20: Jako administrator chcę ustawić wymiar B2B/OUT dla danego okresu, aby odwzorować różny wymiar (np. odbiory za święta). | G20: • Wymiar ustawiany w panelu admina • Możliwa korekta indywidualna | H20: Must | I20: 3 | J20: MVP | K20: FR-B6 | L20: Zrealizowane
A21: US-B7 | B21: Historyjka | C21: E2 | D21: Wyliczenia, pula i balans | E21: Przełom okresu — rolowanie/wygaszanie urlopu | F21: Jako pracownik chcę, żeby niewykorzystane dni przeszły na kolejny okres rozliczeniowy, aby nie tracić urlopu na przełomie roku. | G21: • Niewykorzystane dni przechodzą do kolejnego okresu jako zaległe, bez terminu wygaśnięcia • Przeniesienie następuje bez działania administratora (także dla osoby bez wiersza puli w nowym okresie) • Zaległe kumulują się przez kolejne okresy • Ręczna korekta administratora nadpisuje wartość wyliczoną i staje się podstawą kolejnych okresów • Licznik na pulpicie i raport wykorzystania pokazują tę samą liczbę dni zaległych | H21: Must | I21: 8 | J21: MVP | K21: FR-B7 | L21: Zrealizowane — reguła rozstrzygnięta (urlop nie przepada); kryteria akceptacji poprawione 10.08.2026
A22: US-B8 | B22: Historyjka | C22: E2 | D22: Wyliczenia, pula i balans | E22: Zmiana formy zatrudnienia w trakcie roku | F22: Jako system chcę zastosować właściwe reguły po zmianie formy (np. B2B→UoP), aby zachować poprawność wyliczeń i historię. | G22: • Po dacie zmiany obowiązuje właściwy okres • Historia sprzed zmiany zachowana | H22: Should | I22: 5 | J22: Faza 2 | K22: FR-B8 | L22: Zrealizowane
A23: US-B9 | B23: Historyjka | C23: E2 | D23: Wyliczenia, pula i balans | E23: Proporcjonalne naliczanie puli (proration) | F23: Jako system chcę naliczać pulę proporcjonalnie przy wejściu/odejściu w trakcie okresu, aby sprawiedliwie liczyć limit dla nowych i odchodzących. | G23: • Pula proporcjonalna do okresu zatrudnienia • Nieobecności po dacie odejścia sygnalizowane | H23: Should | I23: 5 | J23: Faza 2 | K23: FR-B9 | L23: Zrealizowane
A24: US-B10 | B24: Historyjka | C24: E2 | D24: Wyliczenia, pula i balans | E24: Konwersja zaplanowanej nieobecności na L4 | F24: Jako osoba z uprawnieniem rozszerzonym chcę zamienić zaplanowany urlop na L4 po fakcie, aby oddać dzień do puli, gdy pracownik zachorował. | G24: • Dzień zamieniony na L4 wraca do puli UoP • Zmiana odnotowana w historii | H24: Should | I24: 3 | J24: Faza 2 | K24: FR-B10 | L24: Zrealizowane
A25: E3 | B25: Epik | C25: E3 | D25: Kalendarz i widoki zespołu | E25: Kalendarz i widoki zespołu | F25: Wspólny, jednolity widok nieobecności w obrębie Tribe.
A26: US-C1 | B26: Historyjka | C26: E3 | D26: Kalendarz i widoki zespołu | E26: Kalendarz zespołu (tydzień/miesiąc) | F26: Jako lider / pracownik chcę widzieć nieobecności zespołu w kalendarzu, aby planować pracę z wyprzedzeniem. | G26: • Widok tygodniowy i miesięczny • Prezentacja osób w obrębie Tribe • Możliwość filtrowania | H26: Must | I26: 8 | J26: MVP | K26: FR-C1 | L26: Zrealizowane
A27: US-C2 | B27: Historyjka | C27: E3 | D27: Kalendarz i widoki zespołu | E27: Filtr „kto dziś / w tym tygodniu nieobecny” | F27: Jako lider chcę szybko zawęzić widok do nieobecnych, aby ocenić bieżącą dostępność zespołu. | G27: • Filtr zawęża do wybranego horyzontu • Wynik aktualny na bieżący dzień/tydzień | H27: Should | I27: 2 | J27: Faza 2 | K27: FR-C2 | L27: Zrealizowane
A28: US-C3 | B28: Historyjka | C28: E3 | D28: Kalendarz i widoki zespołu | E28: Jednolita prezentacja nieobecności | F28: Jako pracownik chcę widzieć wszystkie nieobecności jednolicie (bez kolorów per typ), aby chronić prywatność i uprościć odbiór. | G28: • Brak kolorów per typ • L4 wyświetlane jak zwykła nieobecność (bez etykiety „chorobowe”) | H28: Must | I28: 3 | J28: MVP | K28: FR-C3 | L28: Zrealizowane
A29: US-C4 | B29: Historyjka | C29: E3 | D29: Kalendarz i widoki zespołu | E29: Heatmapa pokrycia zespołu | F29: Jako lider chcę zobaczyć natężenie nieobecności w czasie, aby wykryć okresy ryzyka pokrycia. | G29: • Okresy o wysokim odsetku nieobecności wyróżnione | H29: Could | I29: 5 | J29: Faza 3 | K29: FR-C4 | L29: Zrealizowane
A30: US-C5 | B30: Historyjka | C30: E3 | D30: Kalendarz i widoki zespołu | E30: Pulpit startowy | F30: Jako pracownik chcę mieć po zalogowaniu mój balans, kto nieobecny i przypomnienia, aby od razu widzieć najważniejsze informacje. | G30: • Domyślny ekran prezentuje balans, listę nieobecnych i przypomnienia • Brak dodatkowej nawigacji do kluczowych danych | H30: Should | I30: 5 | J30: Faza 2 | K30: FR-C5 | L30: Zrealizowane
A31: E4 | B31: Epik | C31: E4 | D31: Planowanie capacity i sprinty | E31: Planowanie capacity i sprinty | F31: Wsparcie planowania sprintów i ostrzeganie o ryzyku pokrycia ról.
A32: US-D1 | B32: Historyjka | C32: E4 | D32: Planowanie capacity i sprinty | E32: Widok sprintowy nieobecności | F32: Jako Product Owner / Agile PM chcę widzieć nieobecności w podziale na sprinty, aby planować zakres sprintu realistycznie. | G32: • Wybór sprintu • Podgląd nieobecności i capacity squadu w sprincie | H32: Should | I32: 5 | J32: Faza 2 | K32: FR-D1 | L32: Zrealizowane
A33: US-D2 | B33: Historyjka | C33: E4 | D33: Planowanie capacity i sprinty | E33: Wyliczenie capacity squadu per sprint | F33: Jako Product Owner / Agile PM chcę mieć policzone capacity squadu na sprint, aby oszacować realny potencjał wykonawczy. | G33: • Capacity pomniejszone o nieobecności i niepełne dni • Przeliczane automatycznie na bazie wpisów i kalendarza sprintów | H33: Must | I33: 5 | J33: MVP | K33: FR-D2 | L33: Zrealizowane
A34: US-D3 | B34: Historyjka | C34: E4 | D34: Planowanie capacity i sprinty | E34: Alert kolizji kluczowych ról | F34: Jako Product Owner / lider chcę otrzymać ostrzeżenie, gdy kluczowe role są nieobecne jednocześnie, aby ograniczyć ryzyko ciągłości. | G34: • Role kluczowe oznacza administrator • System sygnalizuje nakładające się nieobecności kluczowych ról | H34: Must | I34: 5 | J34: MVP | K34: FR-D3 | L34: Zrealizowane
A35: US-D4 | B35: Historyjka | C35: E4 | D35: Planowanie capacity i sprinty | E35: Import harmonogramu sprintów | F35: Jako administrator chcę zaimportować harmonogram sprintów z pliku .xlsx, aby zasilić widoki i wyliczenia sprintowe. | G35: • Import .xlsx ram sprintów • Ramy używane w widokach i capacity | H35: Must | I35: 3 | J35: MVP | K35: FR-D4 | L35: Zrealizowane — układ kolumn pliku konfigurowalny do czasu decyzji zamawiającego
A36: E5 | B36: Epik | C36: E5 | D36: Powiadomienia | E36: Powiadomienia | F36: Informowanie liderów i pracowników o istotnych zdarzeniach.
A37: US-E1 | B37: Historyjka | C37: E5 | D37: Powiadomienia | E37: Powiadomienie lidera o nieobecności B2B/OUT | F37: Jako lider chcę dostać e-mail o planowanej nieobecności B2B/OUT, aby być informowanym bez formalnej akceptacji. | G37: • E-mail do lidera < 5 min od zapisania wpisu B2B/OUT • Charakter informacyjny (bez zatwierdzania) | H37: Should | I37: 3 | J37: Faza 2 | K37: FR-E1 | L37: Zrealizowane
A38: US-E2 | B38: Historyjka | C38: E5 | D38: Powiadomienia | E38: Wpis bez formalnej akceptacji | F38: Jako pracownik chcę mieć wpis obowiązujący od zapisania, aby uniknąć zbędnego obiegu akceptacji. | G38: • Wpis widoczny i uwzględniony w wyliczeniach bez zatwierdzania | H38: Must | I38: 1 | J38: MVP | K38: FR-E2 | L38: Zrealizowane
A39: US-E3 | B39: Historyjka | C39: E5 | D39: Powiadomienia | E39: Przypomnienia o zaległym/niewybranym urlopie | F39: Jako pracownik chcę otrzymywać przypomnienia o zaległym urlopie, aby wykorzystać dni zanim przepadną. | G39: • Przypomnienie wg reguły administratora • Opcjonalna kopia do lidera | H39: Should | I39: 5 | J39: Faza 2 | K39: FR-E3 | L39: Zrealizowane
A40: US-E4 | B40: Historyjka | C40: E5 | D40: Powiadomienia | E40: Kanał powiadomień e-mail | F40: Jako system chcę wysyłać powiadomienia e-mailem, aby dostarczać informacje w MVP bez dodatkowych kanałów. | G40: • Powiadomienia dostarczane e-mailem < 5 min od zdarzenia | H40: Should | I40: 3 | J40: Faza 2 | K40: FR-E4 | L40: Zrealizowane
...

Sheet Epiki
A1: Epik ID | B1: Nazwa | C1: Cel | D1: Liczba historyjek | E1: Suma story points | F1: Historyjki MVP
A2: E1 | B2: Rejestracja i zarządzanie nieobecnościami | C2: Pracownicy samodzielnie wpisują i edytują nieobecności bez blokad pliku. | D2: =COUNTIFS(Backlog!C:C,A2,Backlog!B:B,"Historyjka") -> 11 | E2: =SUMIFS(Backlog!I:I,Backlog!C:C,A2,Backlog!B:B,"Historyjka") -> 47 | F2: =COUNTIFS(Backlog!C:C,A2,Backlog!B:B,"Historyjka",Backlog!J:J,"MVP") -> 6
A3: E2 | B3: Wyliczenia, pula i balans | C3: Poprawne, odrębne liczenie urlopu dla UoP i B2B/OUT wraz z przypadkami brzegowymi. | D3: =COUNTIFS(Backlog!C:C,A3,Backlog!B:B,"Historyjka") -> 11 | E3: =SUMIFS(Backlog!I:I,Backlog!C:C,A3,Backlog!B:B,"Historyjka") -> 53 | F3: =COUNTIFS(Backlog!C:C,A3,Backlog!B:B,"Historyjka",Backlog!J:J,"MVP") -> 7
A4: E3 | B4: Kalendarz i widoki zespołu | C4: Wspólny, jednolity widok nieobecności w obrębie Tribe. | D4: =COUNTIFS(Backlog!C:C,A4,Backlog!B:B,"Historyjka") -> 7 | E4: =SUMIFS(Backlog!I:I,Backlog!C:C,A4,Backlog!B:B,"Historyjka") -> 27 | F4: =COUNTIFS(Backlog!C:C,A4,Backlog!B:B,"Historyjka",Backlog!J:J,"MVP") -> 2
A5: E4 | B5: Planowanie capacity i sprinty | C5: Wsparcie planowania sprintów i ostrzeganie o ryzyku pokrycia ról. | D5: =COUNTIFS(Backlog!C:C,A5,Backlog!B:B,"Historyjka") -> 4 | E5: =SUMIFS(Backlog!I:I,Backlog!C:C,A5,Backlog!B:B,"Historyjka") -> 18 | F5: =COUNTIFS(Backlog!C:C,A5,Backlog!B:B,"Historyjka",Backlog!J:J,"MVP") -> 3
A6: E5 | B6: Powiadomienia | C6: Informowanie liderów i pracowników o istotnych zdarzeniach. | D6: =COUNTIFS(Backlog!C:C,A6,Backlog!B:B,"Historyjka") -> 5 | E6: =SUMIFS(Backlog!I:I,Backlog!C:C,A6,Backlog!B:B,"Historyjka") -> 15 | F6: =COUNTIFS(Backlog!C:C,A6,Backlog!B:B,"Historyjka",Backlog!J:J,"MVP") -> 1
A7: E6 | B7: Raporty i eksport | C7: Raportowanie z drążeniem hierarchii i eksportem do Excela. | D7: =COUNTIFS(Backlog!C:C,A7,Backlog!B:B,"Historyjka") -> 6 | E7: =SUMIFS(Backlog!I:I,Backlog!C:C,A7,Backlog!B:B,"Historyjka") -> 31 | F7: =COUNTIFS(Backlog!C:C,A7,Backlog!B:B,"Historyjka",Backlog!J:J,"MVP") -> 3
A8: E7 | B8: Administracja | C8: Konfiguracja typów, puli, świąt, struktury i sprintów. | D8: =COUNTIFS(Backlog!C:C,A8,Backlog!B:B,"Historyjka") -> 8 | E8: =SUMIFS(Backlog!I:I,Backlog!C:C,A8,Backlog!B:B,"Historyjka") -> 40 | F8: =COUNTIFS(Backlog!C:C,A8,Backlog!B:B,"Historyjka",Backlog!J:J,"MVP") -> 6
A9: E8 | B9: Uprawnienia, role i logowanie | C9: Kontrola dostępu, delegacja uprawnień i uwierzytelnianie. | D9: =COUNTIFS(Backlog!C:C,A9,Backlog!B:B,"Historyjka") -> 5 | E9: =SUMIFS(Backlog!I:I,Backlog!C:C,A9,Backlog!B:B,"Historyjka") -> 25 | F9: =COUNTIFS(Backlog!C:C,A9,Backlog!B:B,"Historyjka",Backlog!J:J,"MVP") -> 5
A10: E9 | B10: Audyt i historia | C10: Śledzenie zmian i wgląd we własną historię wpisów. | D10: =COUNTIFS(Backlog!C:C,A10,Backlog!B:B,"Historyjka") -> 3 | E10: =SUMIFS(Backlog!I:I,Backlog!C:C,A10,Backlog!B:B,"Historyjka") -> 11 | F10: =COUNTIFS(Backlog!C:C,A10,Backlog!B:B,"Historyjka",Backlog!J:J,"MVP") -> 0
A11: E10 | B11: Bezpieczeństwo i zgodność (RODO) | C11: Ochrona danych o zdrowiu (L4) i zgodność z RODO. | D11: =COUNTIFS(Backlog!C:C,A11,Backlog!B:B,"Historyjka") -> 4 | E11: =SUMIFS(Backlog!I:I,Backlog!C:C,A11,Backlog!B:B,"Historyjka") -> 16 | F11: =COUNTIFS(Backlog!C:C,A11,Backlog!B:B,"Historyjka",Backlog!J:J,"MVP") -> 3
A12: E11 | B12: Platforma i wymagania niefunkcjonalne | C12: Wydajność, bezpieczeństwo, backup, dostępność i analityka. | D12: =COUNTIFS(Backlog!C:C,A12,Backlog!B:B,"Historyjka") -> 9 | E12: =SUMIFS(Backlog!I:I,Backlog!C:C,A12,Backlog!B:B,"Historyjka") -> 40 | F12: =COUNTIFS(Backlog!C:C,A12,Backlog!B:B,"Historyjka",Backlog!J:J,"MVP") -> 5
A13: RAZEM | D13: =SUM(D2:D12) -> 73 | E13: =SUM(E2:E12) -> 323 | F13: =SUM(F2:F12) -> 41

Sheet Legenda
A1: Element | B1: Znaczenie
A2: Priorytet — Must | B2: Konieczne w MVP (zakres minimalny).
A3: Priorytet — Should | B3: Ważne, planowane w Fazie 2.
A4: Priorytet — Could | B4: Opcjonalne, Faza 3 / docelowo.
A5: Priorytet — Won't | B5: Poza zakresem MVP.
A6: Story points | B6: Szacunek złożoności w skali Fibonacciego (1,2,3,5,8,13). Do kalibracji przez zespół.
A7: Faza | B7: Przypisanie do wdrożenia: MVP / Faza 2 / Faza 3 (wg Załącznika C dokumentu wymagań).
A8: Ref. FR/NFR | B8: Odniesienie do wymagania w dokumencie „Wymagania funkcjonalne i niefunkcjonalne v2.0”.
A9: Import do JIRA | B9: Arkusz „Backlog”: kolumna „Typ zgłoszenia” = Epik/Historyjka; „Epik”/„Epik ID” służą do powiązania historyjek z epikami.
A10: Stan wdrożenia — Zrealizowane | B10: Funkcja działa w aplikacji; pokryta testami silnika lub suitą integracyjną.
A11: Stan wdrożenia — ODSTĘPSTWO | B11: Zakres świadomie zawężony w stosunku do wymagania. Wymaga potwierdzenia zamawiającego.
A12: Stan wdrożenia — Niezrealizowane | B12: Nie zbudowane; powód podany w treści komórki.
... A14: Aktualizacja stanu | B14: Kolumna „Stan wdrożenia" odzwierciedla przegląd kodu i przebieg weryfikacji z 10.08.2026.
